[2025-04-17 17:59:23] [INFO] root: Logging has been set up.
[2025-04-17 17:59:23] [ERROR] root: Database initialization failed: (pyodbc.Error) ('IM012', '[IM012] [Microsoft][ODBC Driver Manager] DRIVER keyword syntax error (0) (SQLDriverConnect)')
(Background on this error at: https://sqlalche.me/e/20/dbapi)
Traceback (most recent call last):
  File "C:\Users\khuat\AppData\Roaming\Python\Python313\site-packages\sqlalchemy\engine\base.py", line 146, in __init__
    self._dbapi_connection = engine.raw_connection()
                             ~~~~~~~~~~~~~~~~~~~~~^^
  File "C:\Users\khuat\AppData\Roaming\Python\Python313\site-packages\sqlalchemy\engine\base.py", line 3298, in raw_connection
    return self.pool.connect()
           ~~~~~~~~~~~~~~~~~^^
  File "C:\Users\khuat\AppData\Roaming\Python\Python313\site-packages\sqlalchemy\pool\base.py", line 449, in connect
    return _ConnectionFairy._checkout(self)
           ~~~~~~~~~~~~~~~~~~~~~~~~~~^^^^^^
  File "C:\Users\khuat\AppData\Roaming\Python\Python313\site-packages\sqlalchemy\pool\base.py", line 1264, in _checkout
    fairy = _ConnectionRecord.checkout(pool)
  File "C:\Users\khuat\AppData\Roaming\Python\Python313\site-packages\sqlalchemy\pool\base.py", line 713, in checkout
    rec = pool._do_get()
  File "C:\Users\khuat\AppData\Roaming\Python\Python313\site-packages\sqlalchemy\pool\impl.py", line 179, in _do_get
    with util.safe_reraise():
         ~~~~~~~~~~~~~~~~~^^
  File "C:\Users\khuat\AppData\Roaming\Python\Python313\site-packages\sqlalchemy\util\langhelpers.py", line 146, in __exit__
    raise exc_value.with_traceback(exc_tb)
  File "C:\Users\khuat\AppData\Roaming\Python\Python313\site-packages\sqlalchemy\pool\impl.py", line 177, in _do_get
    return self._create_connection()
           ~~~~~~~~~~~~~~~~~~~~~~~^^
  File "C:\Users\khuat\AppData\Roaming\Python\Python313\site-packages\sqlalchemy\pool\base.py", line 390, in _create_connection
    return _ConnectionRecord(self)
  File "C:\Users\khuat\AppData\Roaming\Python\Python313\site-packages\sqlalchemy\pool\base.py", line 675, in __init__
    self.__connect()
    ~~~~~~~~~~~~~~^^
  File "C:\Users\khuat\AppData\Roaming\Python\Python313\site-packages\sqlalchemy\pool\base.py", line 901, in __connect
    with util.safe_reraise():
         ~~~~~~~~~~~~~~~~~^^
  File "C:\Users\khuat\AppData\Roaming\Python\Python313\site-packages\sqlalchemy\util\langhelpers.py", line 146, in __exit__
    raise exc_value.with_traceback(exc_tb)
  File "C:\Users\khuat\AppData\Roaming\Python\Python313\site-packages\sqlalchemy\pool\base.py", line 897, in __connect
    self.dbapi_connection = connection = pool._invoke_creator(self)
                                         ~~~~~~~~~~~~~~~~~~~~^^^^^^
  File "C:\Users\khuat\AppData\Roaming\Python\Python313\site-packages\sqlalchemy\engine\create.py", line 646, in connect
    return dialect.connect(*cargs, **cparams)
           ~~~~~~~~~~~~~~~^^^^^^^^^^^^^^^^^^^
  File "C:\Users\khuat\AppData\Roaming\Python\Python313\site-packages\sqlalchemy\engine\default.py", line 625, in connect
    return self.loaded_dbapi.connect(*cargs, **cparams)  # type: ignore[no-any-return]  # NOQA: E501
           ~~~~~~~~~~~~~~~~~~~~~~~~~^^^^^^^^^^^^^^^^^^^
pyodbc.Error: ('IM012', '[IM012] [Microsoft][ODBC Driver Manager] DRIVER keyword syntax error (0) (SQLDriverConnect)')

The above exception was the direct cause of the following exception:

Traceback (most recent call last):
  File "c:\Studii\ltweb\app.py", line 98, in initialize_database
    Base.metadata.create_all(engine)
    ~~~~~~~~~~~~~~~~~~~~~~~~^^^^^^^^
  File "C:\Users\khuat\AppData\Roaming\Python\Python313\site-packages\sqlalchemy\sql\schema.py", line 5925, in create_all
    bind._run_ddl_visitor(
    ~~~~~~~~~~~~~~~~~~~~~^
        ddl.SchemaGenerator, self, checkfirst=checkfirst, tables=tables
        ^^^^^^^^^^^^^^^^^^^^^^^^^^^^^^^^^^^^^^^^^^^^^^^^^^^^^^^^^^^^^^^
    )
    ^
  File "C:\Users\khuat\AppData\Roaming\Python\Python313\site-packages\sqlalchemy\engine\base.py", line 3248, in _run_ddl_visitor
    with self.begin() as conn:
         ~~~~~~~~~~^^
  File "C:\Python313\Lib\contextlib.py", line 141, in __enter__
    return next(self.gen)
  File "C:\Users\khuat\AppData\Roaming\Python\Python313\site-packages\sqlalchemy\engine\base.py", line 3238, in begin
    with self.connect() as conn:
         ~~~~~~~~~~~~^^
  File "C:\Users\khuat\AppData\Roaming\Python\Python313\site-packages\sqlalchemy\engine\base.py", line 3274, in connect
    return self._connection_cls(self)
           ~~~~~~~~~~~~~~~~~~~~^^^^^^
  File "C:\Users\khuat\AppData\Roaming\Python\Python313\site-packages\sqlalchemy\engine\base.py", line 148, in __init__
    Connection._handle_dbapi_exception_noconnection(
    ~~~~~~~~~~~~~~~~~~~~~~~~~~~~~~~~~~~~~~~~~~~~~~~^
        err, dialect, engine
        ^^^^^^^^^^^^^^^^^^^^
    )
    ^
  File "C:\Users\khuat\AppData\Roaming\Python\Python313\site-packages\sqlalchemy\engine\base.py", line 2439, in _handle_dbapi_exception_noconnection
    raise sqlalchemy_exception.with_traceback(exc_info[2]) from e
  File "C:\Users\khuat\AppData\Roaming\Python\Python313\site-packages\sqlalchemy\engine\base.py", line 146, in __init__
    self._dbapi_connection = engine.raw_connection()
                             ~~~~~~~~~~~~~~~~~~~~~^^
  File "C:\Users\khuat\AppData\Roaming\Python\Python313\site-packages\sqlalchemy\engine\base.py", line 3298, in raw_connection
    return self.pool.connect()
           ~~~~~~~~~~~~~~~~~^^
  File "C:\Users\khuat\AppData\Roaming\Python\Python313\site-packages\sqlalchemy\pool\base.py", line 449, in connect
    return _ConnectionFairy._checkout(self)
           ~~~~~~~~~~~~~~~~~~~~~~~~~~^^^^^^
  File "C:\Users\khuat\AppData\Roaming\Python\Python313\site-packages\sqlalchemy\pool\base.py", line 1264, in _checkout
    fairy = _ConnectionRecord.checkout(pool)
  File "C:\Users\khuat\AppData\Roaming\Python\Python313\site-packages\sqlalchemy\pool\base.py", line 713, in checkout
    rec = pool._do_get()
  File "C:\Users\khuat\AppData\Roaming\Python\Python313\site-packages\sqlalchemy\pool\impl.py", line 179, in _do_get
    with util.safe_reraise():
         ~~~~~~~~~~~~~~~~~^^
  File "C:\Users\khuat\AppData\Roaming\Python\Python313\site-packages\sqlalchemy\util\langhelpers.py", line 146, in __exit__
    raise exc_value.with_traceback(exc_tb)
  File "C:\Users\khuat\AppData\Roaming\Python\Python313\site-packages\sqlalchemy\pool\impl.py", line 177, in _do_get
    return self._create_connection()
           ~~~~~~~~~~~~~~~~~~~~~~~^^
  File "C:\Users\khuat\AppData\Roaming\Python\Python313\site-packages\sqlalchemy\pool\base.py", line 390, in _create_connection
    return _ConnectionRecord(self)
  File "C:\Users\khuat\AppData\Roaming\Python\Python313\site-packages\sqlalchemy\pool\base.py", line 675, in __init__
    self.__connect()
    ~~~~~~~~~~~~~~^^
  File "C:\Users\khuat\AppData\Roaming\Python\Python313\site-packages\sqlalchemy\pool\base.py", line 901, in __connect
    with util.safe_reraise():
         ~~~~~~~~~~~~~~~~~^^
  File "C:\Users\khuat\AppData\Roaming\Python\Python313\site-packages\sqlalchemy\util\langhelpers.py", line 146, in __exit__
    raise exc_value.with_traceback(exc_tb)
  File "C:\Users\khuat\AppData\Roaming\Python\Python313\site-packages\sqlalchemy\pool\base.py", line 897, in __connect
    self.dbapi_connection = connection = pool._invoke_creator(self)
                                         ~~~~~~~~~~~~~~~~~~~~^^^^^^
  File "C:\Users\khuat\AppData\Roaming\Python\Python313\site-packages\sqlalchemy\engine\create.py", line 646, in connect
    return dialect.connect(*cargs, **cparams)
           ~~~~~~~~~~~~~~~^^^^^^^^^^^^^^^^^^^
  File "C:\Users\khuat\AppData\Roaming\Python\Python313\site-packages\sqlalchemy\engine\default.py", line 625, in connect
    return self.loaded_dbapi.connect(*cargs, **cparams)  # type: ignore[no-any-return]  # NOQA: E501
           ~~~~~~~~~~~~~~~~~~~~~~~~~^^^^^^^^^^^^^^^^^^^
sqlalchemy.exc.DBAPIError: (pyodbc.Error) ('IM012', '[IM012] [Microsoft][ODBC Driver Manager] DRIVER keyword syntax error (0) (SQLDriverConnect)')
(Background on this error at: https://sqlalche.me/e/20/dbapi)
[2025-04-17 17:59:43] [INFO] root: Logging has been set up.
[2025-04-17 17:59:43] [ERROR] root: Database initialization failed: (pyodbc.Error) ('IM012', '[IM012] [Microsoft][ODBC Driver Manager] DRIVER keyword syntax error (0) (SQLDriverConnect)')
(Background on this error at: https://sqlalche.me/e/20/dbapi)
Traceback (most recent call last):
  File "C:\Users\khuat\AppData\Roaming\Python\Python313\site-packages\sqlalchemy\engine\base.py", line 146, in __init__
    self._dbapi_connection = engine.raw_connection()
                             ~~~~~~~~~~~~~~~~~~~~~^^
  File "C:\Users\khuat\AppData\Roaming\Python\Python313\site-packages\sqlalchemy\engine\base.py", line 3298, in raw_connection
    return self.pool.connect()
           ~~~~~~~~~~~~~~~~~^^
  File "C:\Users\khuat\AppData\Roaming\Python\Python313\site-packages\sqlalchemy\pool\base.py", line 449, in connect
    return _ConnectionFairy._checkout(self)
           ~~~~~~~~~~~~~~~~~~~~~~~~~~^^^^^^
  File "C:\Users\khuat\AppData\Roaming\Python\Python313\site-packages\sqlalchemy\pool\base.py", line 1264, in _checkout
    fairy = _ConnectionRecord.checkout(pool)
  File "C:\Users\khuat\AppData\Roaming\Python\Python313\site-packages\sqlalchemy\pool\base.py", line 713, in checkout
    rec = pool._do_get()
  File "C:\Users\khuat\AppData\Roaming\Python\Python313\site-packages\sqlalchemy\pool\impl.py", line 179, in _do_get
    with util.safe_reraise():
         ~~~~~~~~~~~~~~~~~^^
  File "C:\Users\khuat\AppData\Roaming\Python\Python313\site-packages\sqlalchemy\util\langhelpers.py", line 146, in __exit__
    raise exc_value.with_traceback(exc_tb)
  File "C:\Users\khuat\AppData\Roaming\Python\Python313\site-packages\sqlalchemy\pool\impl.py", line 177, in _do_get
    return self._create_connection()
           ~~~~~~~~~~~~~~~~~~~~~~~^^
  File "C:\Users\khuat\AppData\Roaming\Python\Python313\site-packages\sqlalchemy\pool\base.py", line 390, in _create_connection
    return _ConnectionRecord(self)
  File "C:\Users\khuat\AppData\Roaming\Python\Python313\site-packages\sqlalchemy\pool\base.py", line 675, in __init__
    self.__connect()
    ~~~~~~~~~~~~~~^^
  File "C:\Users\khuat\AppData\Roaming\Python\Python313\site-packages\sqlalchemy\pool\base.py", line 901, in __connect
    with util.safe_reraise():
         ~~~~~~~~~~~~~~~~~^^
  File "C:\Users\khuat\AppData\Roaming\Python\Python313\site-packages\sqlalchemy\util\langhelpers.py", line 146, in __exit__
    raise exc_value.with_traceback(exc_tb)
  File "C:\Users\khuat\AppData\Roaming\Python\Python313\site-packages\sqlalchemy\pool\base.py", line 897, in __connect
    self.dbapi_connection = connection = pool._invoke_creator(self)
                                         ~~~~~~~~~~~~~~~~~~~~^^^^^^
  File "C:\Users\khuat\AppData\Roaming\Python\Python313\site-packages\sqlalchemy\engine\create.py", line 646, in connect
    return dialect.connect(*cargs, **cparams)
           ~~~~~~~~~~~~~~~^^^^^^^^^^^^^^^^^^^
  File "C:\Users\khuat\AppData\Roaming\Python\Python313\site-packages\sqlalchemy\engine\default.py", line 625, in connect
    return self.loaded_dbapi.connect(*cargs, **cparams)  # type: ignore[no-any-return]  # NOQA: E501
           ~~~~~~~~~~~~~~~~~~~~~~~~~^^^^^^^^^^^^^^^^^^^
pyodbc.Error: ('IM012', '[IM012] [Microsoft][ODBC Driver Manager] DRIVER keyword syntax error (0) (SQLDriverConnect)')

The above exception was the direct cause of the following exception:

Traceback (most recent call last):
  File "c:\Studii\ltweb\app.py", line 98, in initialize_database
    Base.metadata.create_all(engine)
    ~~~~~~~~~~~~~~~~~~~~~~~~^^^^^^^^
  File "C:\Users\khuat\AppData\Roaming\Python\Python313\site-packages\sqlalchemy\sql\schema.py", line 5925, in create_all
    bind._run_ddl_visitor(
    ~~~~~~~~~~~~~~~~~~~~~^
        ddl.SchemaGenerator, self, checkfirst=checkfirst, tables=tables
        ^^^^^^^^^^^^^^^^^^^^^^^^^^^^^^^^^^^^^^^^^^^^^^^^^^^^^^^^^^^^^^^
    )
    ^
  File "C:\Users\khuat\AppData\Roaming\Python\Python313\site-packages\sqlalchemy\engine\base.py", line 3248, in _run_ddl_visitor
    with self.begin() as conn:
         ~~~~~~~~~~^^
  File "C:\Python313\Lib\contextlib.py", line 141, in __enter__
    return next(self.gen)
  File "C:\Users\khuat\AppData\Roaming\Python\Python313\site-packages\sqlalchemy\engine\base.py", line 3238, in begin
    with self.connect() as conn:
         ~~~~~~~~~~~~^^
  File "C:\Users\khuat\AppData\Roaming\Python\Python313\site-packages\sqlalchemy\engine\base.py", line 3274, in connect
    return self._connection_cls(self)
           ~~~~~~~~~~~~~~~~~~~~^^^^^^
  File "C:\Users\khuat\AppData\Roaming\Python\Python313\site-packages\sqlalchemy\engine\base.py", line 148, in __init__
    Connection._handle_dbapi_exception_noconnection(
    ~~~~~~~~~~~~~~~~~~~~~~~~~~~~~~~~~~~~~~~~~~~~~~~^
        err, dialect, engine
        ^^^^^^^^^^^^^^^^^^^^
    )
    ^
  File "C:\Users\khuat\AppData\Roaming\Python\Python313\site-packages\sqlalchemy\engine\base.py", line 2439, in _handle_dbapi_exception_noconnection
    raise sqlalchemy_exception.with_traceback(exc_info[2]) from e
  File "C:\Users\khuat\AppData\Roaming\Python\Python313\site-packages\sqlalchemy\engine\base.py", line 146, in __init__
    self._dbapi_connection = engine.raw_connection()
                             ~~~~~~~~~~~~~~~~~~~~~^^
  File "C:\Users\khuat\AppData\Roaming\Python\Python313\site-packages\sqlalchemy\engine\base.py", line 3298, in raw_connection
    return self.pool.connect()
           ~~~~~~~~~~~~~~~~~^^
  File "C:\Users\khuat\AppData\Roaming\Python\Python313\site-packages\sqlalchemy\pool\base.py", line 449, in connect
    return _ConnectionFairy._checkout(self)
           ~~~~~~~~~~~~~~~~~~~~~~~~~~^^^^^^
  File "C:\Users\khuat\AppData\Roaming\Python\Python313\site-packages\sqlalchemy\pool\base.py", line 1264, in _checkout
    fairy = _ConnectionRecord.checkout(pool)
  File "C:\Users\khuat\AppData\Roaming\Python\Python313\site-packages\sqlalchemy\pool\base.py", line 713, in checkout
    rec = pool._do_get()
  File "C:\Users\khuat\AppData\Roaming\Python\Python313\site-packages\sqlalchemy\pool\impl.py", line 179, in _do_get
    with util.safe_reraise():
         ~~~~~~~~~~~~~~~~~^^
  File "C:\Users\khuat\AppData\Roaming\Python\Python313\site-packages\sqlalchemy\util\langhelpers.py", line 146, in __exit__
    raise exc_value.with_traceback(exc_tb)
  File "C:\Users\khuat\AppData\Roaming\Python\Python313\site-packages\sqlalchemy\pool\impl.py", line 177, in _do_get
    return self._create_connection()
           ~~~~~~~~~~~~~~~~~~~~~~~^^
  File "C:\Users\khuat\AppData\Roaming\Python\Python313\site-packages\sqlalchemy\pool\base.py", line 390, in _create_connection
    return _ConnectionRecord(self)
  File "C:\Users\khuat\AppData\Roaming\Python\Python313\site-packages\sqlalchemy\pool\base.py", line 675, in __init__
    self.__connect()
    ~~~~~~~~~~~~~~^^
  File "C:\Users\khuat\AppData\Roaming\Python\Python313\site-packages\sqlalchemy\pool\base.py", line 901, in __connect
    with util.safe_reraise():
         ~~~~~~~~~~~~~~~~~^^
  File "C:\Users\khuat\AppData\Roaming\Python\Python313\site-packages\sqlalchemy\util\langhelpers.py", line 146, in __exit__
    raise exc_value.with_traceback(exc_tb)
  File "C:\Users\khuat\AppData\Roaming\Python\Python313\site-packages\sqlalchemy\pool\base.py", line 897, in __connect
    self.dbapi_connection = connection = pool._invoke_creator(self)
                                         ~~~~~~~~~~~~~~~~~~~~^^^^^^
  File "C:\Users\khuat\AppData\Roaming\Python\Python313\site-packages\sqlalchemy\engine\create.py", line 646, in connect
    return dialect.connect(*cargs, **cparams)
           ~~~~~~~~~~~~~~~^^^^^^^^^^^^^^^^^^^
  File "C:\Users\khuat\AppData\Roaming\Python\Python313\site-packages\sqlalchemy\engine\default.py", line 625, in connect
    return self.loaded_dbapi.connect(*cargs, **cparams)  # type: ignore[no-any-return]  # NOQA: E501
           ~~~~~~~~~~~~~~~~~~~~~~~~~^^^^^^^^^^^^^^^^^^^
sqlalchemy.exc.DBAPIError: (pyodbc.Error) ('IM012', '[IM012] [Microsoft][ODBC Driver Manager] DRIVER keyword syntax error (0) (SQLDriverConnect)')
(Background on this error at: https://sqlalche.me/e/20/dbapi)
[2025-04-17 18:03:25] [INFO] root: Logging has been set up.
[2025-04-17 18:03:25] [INFO] sqlalchemy.engine.Engine: SELECT CAST(SERVERPROPERTY('ProductVersion') AS VARCHAR)
[2025-04-17 18:03:25] [INFO] sqlalchemy.engine.Engine: [raw sql] ()
[2025-04-17 18:03:25] [INFO] sqlalchemy.engine.Engine: SELECT schema_name()
[2025-04-17 18:03:25] [INFO] sqlalchemy.engine.Engine: [generated in 0.00052s] ()
[2025-04-17 18:03:25] [INFO] sqlalchemy.engine.Engine: SELECT CAST('test max support' AS NVARCHAR(max))
[2025-04-17 18:03:25] [INFO] sqlalchemy.engine.Engine: [generated in 0.00046s] ()
[2025-04-17 18:03:25] [INFO] sqlalchemy.engine.Engine: SELECT 1 FROM fn_listextendedproperty(default, default, default, default, default, default, default)
[2025-04-17 18:03:25] [INFO] sqlalchemy.engine.Engine: [generated in 0.00060s] ()
[2025-04-17 18:04:18] [INFO] root: Logging has been set up.
[2025-04-17 18:04:18] [INFO] sqlalchemy.engine.Engine: SELECT CAST(SERVERPROPERTY('ProductVersion') AS VARCHAR)
[2025-04-17 18:04:18] [INFO] sqlalchemy.engine.Engine: [raw sql] ()
[2025-04-17 18:04:18] [INFO] sqlalchemy.engine.Engine: SELECT schema_name()
[2025-04-17 18:04:18] [INFO] sqlalchemy.engine.Engine: [generated in 0.00067s] ()
[2025-04-17 18:04:18] [INFO] sqlalchemy.engine.Engine: SELECT CAST('test max support' AS NVARCHAR(max))
[2025-04-17 18:04:18] [INFO] sqlalchemy.engine.Engine: [generated in 0.00061s] ()
[2025-04-17 18:04:18] [INFO] sqlalchemy.engine.Engine: SELECT 1 FROM fn_listextendedproperty(default, default, default, default, default, default, default)
[2025-04-17 18:04:18] [INFO] sqlalchemy.engine.Engine: [generated in 0.00066s] ()
[2025-04-17 18:14:06] [INFO] root: Logging has been set up.
[2025-04-17 18:14:06] [CRITICAL] database.models: Database initialization failed: (pyodbc.Error) ('IM012', '[IM012] [Microsoft][ODBC Driver Manager] DRIVER keyword syntax error (0) (SQLDriverConnect)')
(Background on this error at: https://sqlalche.me/e/20/dbapi)
Traceback (most recent call last):
  File "C:\Users\khuat\AppData\Roaming\Python\Python313\site-packages\sqlalchemy\engine\base.py", line 146, in __init__
    self._dbapi_connection = engine.raw_connection()
                             ~~~~~~~~~~~~~~~~~~~~~^^
  File "C:\Users\khuat\AppData\Roaming\Python\Python313\site-packages\sqlalchemy\engine\base.py", line 3298, in raw_connection
    return self.pool.connect()
           ~~~~~~~~~~~~~~~~~^^
  File "C:\Users\khuat\AppData\Roaming\Python\Python313\site-packages\sqlalchemy\pool\base.py", line 449, in connect
    return _ConnectionFairy._checkout(self)
           ~~~~~~~~~~~~~~~~~~~~~~~~~~^^^^^^
  File "C:\Users\khuat\AppData\Roaming\Python\Python313\site-packages\sqlalchemy\pool\base.py", line 1264, in _checkout
    fairy = _ConnectionRecord.checkout(pool)
  File "C:\Users\khuat\AppData\Roaming\Python\Python313\site-packages\sqlalchemy\pool\base.py", line 713, in checkout
    rec = pool._do_get()
  File "C:\Users\khuat\AppData\Roaming\Python\Python313\site-packages\sqlalchemy\pool\impl.py", line 179, in _do_get
    with util.safe_reraise():
         ~~~~~~~~~~~~~~~~~^^
  File "C:\Users\khuat\AppData\Roaming\Python\Python313\site-packages\sqlalchemy\util\langhelpers.py", line 146, in __exit__
    raise exc_value.with_traceback(exc_tb)
  File "C:\Users\khuat\AppData\Roaming\Python\Python313\site-packages\sqlalchemy\pool\impl.py", line 177, in _do_get
    return self._create_connection()
           ~~~~~~~~~~~~~~~~~~~~~~~^^
  File "C:\Users\khuat\AppData\Roaming\Python\Python313\site-packages\sqlalchemy\pool\base.py", line 390, in _create_connection
    return _ConnectionRecord(self)
  File "C:\Users\khuat\AppData\Roaming\Python\Python313\site-packages\sqlalchemy\pool\base.py", line 675, in __init__
    self.__connect()
    ~~~~~~~~~~~~~~^^
  File "C:\Users\khuat\AppData\Roaming\Python\Python313\site-packages\sqlalchemy\pool\base.py", line 901, in __connect
    with util.safe_reraise():
         ~~~~~~~~~~~~~~~~~^^
  File "C:\Users\khuat\AppData\Roaming\Python\Python313\site-packages\sqlalchemy\util\langhelpers.py", line 146, in __exit__
    raise exc_value.with_traceback(exc_tb)
  File "C:\Users\khuat\AppData\Roaming\Python\Python313\site-packages\sqlalchemy\pool\base.py", line 897, in __connect
    self.dbapi_connection = connection = pool._invoke_creator(self)
                                         ~~~~~~~~~~~~~~~~~~~~^^^^^^
  File "C:\Users\khuat\AppData\Roaming\Python\Python313\site-packages\sqlalchemy\engine\create.py", line 646, in connect
    return dialect.connect(*cargs, **cparams)
           ~~~~~~~~~~~~~~~^^^^^^^^^^^^^^^^^^^
  File "C:\Users\khuat\AppData\Roaming\Python\Python313\site-packages\sqlalchemy\engine\default.py", line 625, in connect
    return self.loaded_dbapi.connect(*cargs, **cparams)  # type: ignore[no-any-return]  # NOQA: E501
           ~~~~~~~~~~~~~~~~~~~~~~~~~^^^^^^^^^^^^^^^^^^^
pyodbc.Error: ('IM012', '[IM012] [Microsoft][ODBC Driver Manager] DRIVER keyword syntax error (0) (SQLDriverConnect)')

The above exception was the direct cause of the following exception:

Traceback (most recent call last):
  File "c:\Studii\ltweb\database\models.py", line 177, in initialize_database
    Base.metadata.create_all(bind=engine)
    ~~~~~~~~~~~~~~~~~~~~~~~~^^^^^^^^^^^^^
  File "C:\Users\khuat\AppData\Roaming\Python\Python313\site-packages\sqlalchemy\sql\schema.py", line 5925, in create_all
    bind._run_ddl_visitor(
    ~~~~~~~~~~~~~~~~~~~~~^
        ddl.SchemaGenerator, self, checkfirst=checkfirst, tables=tables
        ^^^^^^^^^^^^^^^^^^^^^^^^^^^^^^^^^^^^^^^^^^^^^^^^^^^^^^^^^^^^^^^
    )
    ^
  File "C:\Users\khuat\AppData\Roaming\Python\Python313\site-packages\sqlalchemy\engine\base.py", line 3248, in _run_ddl_visitor
    with self.begin() as conn:
         ~~~~~~~~~~^^
  File "C:\Python313\Lib\contextlib.py", line 141, in __enter__
    return next(self.gen)
  File "C:\Users\khuat\AppData\Roaming\Python\Python313\site-packages\sqlalchemy\engine\base.py", line 3238, in begin
    with self.connect() as conn:
         ~~~~~~~~~~~~^^
  File "C:\Users\khuat\AppData\Roaming\Python\Python313\site-packages\sqlalchemy\engine\base.py", line 3274, in connect
    return self._connection_cls(self)
           ~~~~~~~~~~~~~~~~~~~~^^^^^^
  File "C:\Users\khuat\AppData\Roaming\Python\Python313\site-packages\sqlalchemy\engine\base.py", line 148, in __init__
    Connection._handle_dbapi_exception_noconnection(
    ~~~~~~~~~~~~~~~~~~~~~~~~~~~~~~~~~~~~~~~~~~~~~~~^
        err, dialect, engine
        ^^^^^^^^^^^^^^^^^^^^
    )
    ^
  File "C:\Users\khuat\AppData\Roaming\Python\Python313\site-packages\sqlalchemy\engine\base.py", line 2439, in _handle_dbapi_exception_noconnection
    raise sqlalchemy_exception.with_traceback(exc_info[2]) from e
  File "C:\Users\khuat\AppData\Roaming\Python\Python313\site-packages\sqlalchemy\engine\base.py", line 146, in __init__
    self._dbapi_connection = engine.raw_connection()
                             ~~~~~~~~~~~~~~~~~~~~~^^
  File "C:\Users\khuat\AppData\Roaming\Python\Python313\site-packages\sqlalchemy\engine\base.py", line 3298, in raw_connection
    return self.pool.connect()
           ~~~~~~~~~~~~~~~~~^^
  File "C:\Users\khuat\AppData\Roaming\Python\Python313\site-packages\sqlalchemy\pool\base.py", line 449, in connect
    return _ConnectionFairy._checkout(self)
           ~~~~~~~~~~~~~~~~~~~~~~~~~~^^^^^^
  File "C:\Users\khuat\AppData\Roaming\Python\Python313\site-packages\sqlalchemy\pool\base.py", line 1264, in _checkout
    fairy = _ConnectionRecord.checkout(pool)
  File "C:\Users\khuat\AppData\Roaming\Python\Python313\site-packages\sqlalchemy\pool\base.py", line 713, in checkout
    rec = pool._do_get()
  File "C:\Users\khuat\AppData\Roaming\Python\Python313\site-packages\sqlalchemy\pool\impl.py", line 179, in _do_get
    with util.safe_reraise():
         ~~~~~~~~~~~~~~~~~^^
  File "C:\Users\khuat\AppData\Roaming\Python\Python313\site-packages\sqlalchemy\util\langhelpers.py", line 146, in __exit__
    raise exc_value.with_traceback(exc_tb)
  File "C:\Users\khuat\AppData\Roaming\Python\Python313\site-packages\sqlalchemy\pool\impl.py", line 177, in _do_get
    return self._create_connection()
           ~~~~~~~~~~~~~~~~~~~~~~~^^
  File "C:\Users\khuat\AppData\Roaming\Python\Python313\site-packages\sqlalchemy\pool\base.py", line 390, in _create_connection
    return _ConnectionRecord(self)
  File "C:\Users\khuat\AppData\Roaming\Python\Python313\site-packages\sqlalchemy\pool\base.py", line 675, in __init__
    self.__connect()
    ~~~~~~~~~~~~~~^^
  File "C:\Users\khuat\AppData\Roaming\Python\Python313\site-packages\sqlalchemy\pool\base.py", line 901, in __connect
    with util.safe_reraise():
         ~~~~~~~~~~~~~~~~~^^
  File "C:\Users\khuat\AppData\Roaming\Python\Python313\site-packages\sqlalchemy\util\langhelpers.py", line 146, in __exit__
    raise exc_value.with_traceback(exc_tb)
  File "C:\Users\khuat\AppData\Roaming\Python\Python313\site-packages\sqlalchemy\pool\base.py", line 897, in __connect
    self.dbapi_connection = connection = pool._invoke_creator(self)
                                         ~~~~~~~~~~~~~~~~~~~~^^^^^^
  File "C:\Users\khuat\AppData\Roaming\Python\Python313\site-packages\sqlalchemy\engine\create.py", line 646, in connect
    return dialect.connect(*cargs, **cparams)
           ~~~~~~~~~~~~~~~^^^^^^^^^^^^^^^^^^^
  File "C:\Users\khuat\AppData\Roaming\Python\Python313\site-packages\sqlalchemy\engine\default.py", line 625, in connect
    return self.loaded_dbapi.connect(*cargs, **cparams)  # type: ignore[no-any-return]  # NOQA: E501
           ~~~~~~~~~~~~~~~~~~~~~~~~~^^^^^^^^^^^^^^^^^^^
sqlalchemy.exc.DBAPIError: (pyodbc.Error) ('IM012', '[IM012] [Microsoft][ODBC Driver Manager] DRIVER keyword syntax error (0) (SQLDriverConnect)')
(Background on this error at: https://sqlalche.me/e/20/dbapi)
[2025-04-17 18:14:22] [INFO] root: Logging has been set up.
[2025-04-17 18:14:22] [CRITICAL] database.models: Database initialization failed: (pyodbc.Error) ('IM012', '[IM012] [Microsoft][ODBC Driver Manager] DRIVER keyword syntax error (0) (SQLDriverConnect)')
(Background on this error at: https://sqlalche.me/e/20/dbapi)
Traceback (most recent call last):
  File "C:\Users\khuat\AppData\Roaming\Python\Python313\site-packages\sqlalchemy\engine\base.py", line 146, in __init__
    self._dbapi_connection = engine.raw_connection()
                             ~~~~~~~~~~~~~~~~~~~~~^^
  File "C:\Users\khuat\AppData\Roaming\Python\Python313\site-packages\sqlalchemy\engine\base.py", line 3298, in raw_connection
    return self.pool.connect()
           ~~~~~~~~~~~~~~~~~^^
  File "C:\Users\khuat\AppData\Roaming\Python\Python313\site-packages\sqlalchemy\pool\base.py", line 449, in connect
    return _ConnectionFairy._checkout(self)
           ~~~~~~~~~~~~~~~~~~~~~~~~~~^^^^^^
  File "C:\Users\khuat\AppData\Roaming\Python\Python313\site-packages\sqlalchemy\pool\base.py", line 1264, in _checkout
    fairy = _ConnectionRecord.checkout(pool)
  File "C:\Users\khuat\AppData\Roaming\Python\Python313\site-packages\sqlalchemy\pool\base.py", line 713, in checkout
    rec = pool._do_get()
  File "C:\Users\khuat\AppData\Roaming\Python\Python313\site-packages\sqlalchemy\pool\impl.py", line 179, in _do_get
    with util.safe_reraise():
         ~~~~~~~~~~~~~~~~~^^
  File "C:\Users\khuat\AppData\Roaming\Python\Python313\site-packages\sqlalchemy\util\langhelpers.py", line 146, in __exit__
    raise exc_value.with_traceback(exc_tb)
  File "C:\Users\khuat\AppData\Roaming\Python\Python313\site-packages\sqlalchemy\pool\impl.py", line 177, in _do_get
    return self._create_connection()
           ~~~~~~~~~~~~~~~~~~~~~~~^^
  File "C:\Users\khuat\AppData\Roaming\Python\Python313\site-packages\sqlalchemy\pool\base.py", line 390, in _create_connection
    return _ConnectionRecord(self)
  File "C:\Users\khuat\AppData\Roaming\Python\Python313\site-packages\sqlalchemy\pool\base.py", line 675, in __init__
    self.__connect()
    ~~~~~~~~~~~~~~^^
  File "C:\Users\khuat\AppData\Roaming\Python\Python313\site-packages\sqlalchemy\pool\base.py", line 901, in __connect
    with util.safe_reraise():
         ~~~~~~~~~~~~~~~~~^^
  File "C:\Users\khuat\AppData\Roaming\Python\Python313\site-packages\sqlalchemy\util\langhelpers.py", line 146, in __exit__
    raise exc_value.with_traceback(exc_tb)
  File "C:\Users\khuat\AppData\Roaming\Python\Python313\site-packages\sqlalchemy\pool\base.py", line 897, in __connect
    self.dbapi_connection = connection = pool._invoke_creator(self)
                                         ~~~~~~~~~~~~~~~~~~~~^^^^^^
  File "C:\Users\khuat\AppData\Roaming\Python\Python313\site-packages\sqlalchemy\engine\create.py", line 646, in connect
    return dialect.connect(*cargs, **cparams)
           ~~~~~~~~~~~~~~~^^^^^^^^^^^^^^^^^^^
  File "C:\Users\khuat\AppData\Roaming\Python\Python313\site-packages\sqlalchemy\engine\default.py", line 625, in connect
    return self.loaded_dbapi.connect(*cargs, **cparams)  # type: ignore[no-any-return]  # NOQA: E501
           ~~~~~~~~~~~~~~~~~~~~~~~~~^^^^^^^^^^^^^^^^^^^
pyodbc.Error: ('IM012', '[IM012] [Microsoft][ODBC Driver Manager] DRIVER keyword syntax error (0) (SQLDriverConnect)')

The above exception was the direct cause of the following exception:

Traceback (most recent call last):
  File "c:\Studii\ltweb\database\models.py", line 177, in initialize_database
    Base.metadata.create_all(bind=engine)
    ~~~~~~~~~~~~~~~~~~~~~~~~^^^^^^^^^^^^^
  File "C:\Users\khuat\AppData\Roaming\Python\Python313\site-packages\sqlalchemy\sql\schema.py", line 5925, in create_all
    bind._run_ddl_visitor(
    ~~~~~~~~~~~~~~~~~~~~~^
        ddl.SchemaGenerator, self, checkfirst=checkfirst, tables=tables
        ^^^^^^^^^^^^^^^^^^^^^^^^^^^^^^^^^^^^^^^^^^^^^^^^^^^^^^^^^^^^^^^
    )
    ^
  File "C:\Users\khuat\AppData\Roaming\Python\Python313\site-packages\sqlalchemy\engine\base.py", line 3248, in _run_ddl_visitor
    with self.begin() as conn:
         ~~~~~~~~~~^^
  File "C:\Python313\Lib\contextlib.py", line 141, in __enter__
    return next(self.gen)
  File "C:\Users\khuat\AppData\Roaming\Python\Python313\site-packages\sqlalchemy\engine\base.py", line 3238, in begin
    with self.connect() as conn:
         ~~~~~~~~~~~~^^
  File "C:\Users\khuat\AppData\Roaming\Python\Python313\site-packages\sqlalchemy\engine\base.py", line 3274, in connect
    return self._connection_cls(self)
           ~~~~~~~~~~~~~~~~~~~~^^^^^^
  File "C:\Users\khuat\AppData\Roaming\Python\Python313\site-packages\sqlalchemy\engine\base.py", line 148, in __init__
    Connection._handle_dbapi_exception_noconnection(
    ~~~~~~~~~~~~~~~~~~~~~~~~~~~~~~~~~~~~~~~~~~~~~~~^
        err, dialect, engine
        ^^^^^^^^^^^^^^^^^^^^
    )
    ^
  File "C:\Users\khuat\AppData\Roaming\Python\Python313\site-packages\sqlalchemy\engine\base.py", line 2439, in _handle_dbapi_exception_noconnection
    raise sqlalchemy_exception.with_traceback(exc_info[2]) from e
  File "C:\Users\khuat\AppData\Roaming\Python\Python313\site-packages\sqlalchemy\engine\base.py", line 146, in __init__
    self._dbapi_connection = engine.raw_connection()
                             ~~~~~~~~~~~~~~~~~~~~~^^
  File "C:\Users\khuat\AppData\Roaming\Python\Python313\site-packages\sqlalchemy\engine\base.py", line 3298, in raw_connection
    return self.pool.connect()
           ~~~~~~~~~~~~~~~~~^^
  File "C:\Users\khuat\AppData\Roaming\Python\Python313\site-packages\sqlalchemy\pool\base.py", line 449, in connect
    return _ConnectionFairy._checkout(self)
           ~~~~~~~~~~~~~~~~~~~~~~~~~~^^^^^^
  File "C:\Users\khuat\AppData\Roaming\Python\Python313\site-packages\sqlalchemy\pool\base.py", line 1264, in _checkout
    fairy = _ConnectionRecord.checkout(pool)
  File "C:\Users\khuat\AppData\Roaming\Python\Python313\site-packages\sqlalchemy\pool\base.py", line 713, in checkout
    rec = pool._do_get()
  File "C:\Users\khuat\AppData\Roaming\Python\Python313\site-packages\sqlalchemy\pool\impl.py", line 179, in _do_get
    with util.safe_reraise():
         ~~~~~~~~~~~~~~~~~^^
  File "C:\Users\khuat\AppData\Roaming\Python\Python313\site-packages\sqlalchemy\util\langhelpers.py", line 146, in __exit__
    raise exc_value.with_traceback(exc_tb)
  File "C:\Users\khuat\AppData\Roaming\Python\Python313\site-packages\sqlalchemy\pool\impl.py", line 177, in _do_get
    return self._create_connection()
           ~~~~~~~~~~~~~~~~~~~~~~~^^
  File "C:\Users\khuat\AppData\Roaming\Python\Python313\site-packages\sqlalchemy\pool\base.py", line 390, in _create_connection
    return _ConnectionRecord(self)
  File "C:\Users\khuat\AppData\Roaming\Python\Python313\site-packages\sqlalchemy\pool\base.py", line 675, in __init__
    self.__connect()
    ~~~~~~~~~~~~~~^^
  File "C:\Users\khuat\AppData\Roaming\Python\Python313\site-packages\sqlalchemy\pool\base.py", line 901, in __connect
    with util.safe_reraise():
         ~~~~~~~~~~~~~~~~~^^
  File "C:\Users\khuat\AppData\Roaming\Python\Python313\site-packages\sqlalchemy\util\langhelpers.py", line 146, in __exit__
    raise exc_value.with_traceback(exc_tb)
  File "C:\Users\khuat\AppData\Roaming\Python\Python313\site-packages\sqlalchemy\pool\base.py", line 897, in __connect
    self.dbapi_connection = connection = pool._invoke_creator(self)
                                         ~~~~~~~~~~~~~~~~~~~~^^^^^^
  File "C:\Users\khuat\AppData\Roaming\Python\Python313\site-packages\sqlalchemy\engine\create.py", line 646, in connect
    return dialect.connect(*cargs, **cparams)
           ~~~~~~~~~~~~~~~^^^^^^^^^^^^^^^^^^^
  File "C:\Users\khuat\AppData\Roaming\Python\Python313\site-packages\sqlalchemy\engine\default.py", line 625, in connect
    return self.loaded_dbapi.connect(*cargs, **cparams)  # type: ignore[no-any-return]  # NOQA: E501
           ~~~~~~~~~~~~~~~~~~~~~~~~~^^^^^^^^^^^^^^^^^^^
sqlalchemy.exc.DBAPIError: (pyodbc.Error) ('IM012', '[IM012] [Microsoft][ODBC Driver Manager] DRIVER keyword syntax error (0) (SQLDriverConnect)')
(Background on this error at: https://sqlalche.me/e/20/dbapi)
[2025-04-17 18:14:38] [INFO] root: Logging has been set up.
[2025-04-17 18:14:39] [CRITICAL] database.models: Database initialization failed: (pyodbc.Error) ('IM012', '[IM012] [Microsoft][ODBC Driver Manager] DRIVER keyword syntax error (0) (SQLDriverConnect)')
(Background on this error at: https://sqlalche.me/e/20/dbapi)
Traceback (most recent call last):
  File "C:\Users\khuat\AppData\Roaming\Python\Python313\site-packages\sqlalchemy\engine\base.py", line 146, in __init__
    self._dbapi_connection = engine.raw_connection()
                             ~~~~~~~~~~~~~~~~~~~~~^^
  File "C:\Users\khuat\AppData\Roaming\Python\Python313\site-packages\sqlalchemy\engine\base.py", line 3298, in raw_connection
    return self.pool.connect()
           ~~~~~~~~~~~~~~~~~^^
  File "C:\Users\khuat\AppData\Roaming\Python\Python313\site-packages\sqlalchemy\pool\base.py", line 449, in connect
    return _ConnectionFairy._checkout(self)
           ~~~~~~~~~~~~~~~~~~~~~~~~~~^^^^^^
  File "C:\Users\khuat\AppData\Roaming\Python\Python313\site-packages\sqlalchemy\pool\base.py", line 1264, in _checkout
    fairy = _ConnectionRecord.checkout(pool)
  File "C:\Users\khuat\AppData\Roaming\Python\Python313\site-packages\sqlalchemy\pool\base.py", line 713, in checkout
    rec = pool._do_get()
  File "C:\Users\khuat\AppData\Roaming\Python\Python313\site-packages\sqlalchemy\pool\impl.py", line 179, in _do_get
    with util.safe_reraise():
         ~~~~~~~~~~~~~~~~~^^
  File "C:\Users\khuat\AppData\Roaming\Python\Python313\site-packages\sqlalchemy\util\langhelpers.py", line 146, in __exit__
    raise exc_value.with_traceback(exc_tb)
  File "C:\Users\khuat\AppData\Roaming\Python\Python313\site-packages\sqlalchemy\pool\impl.py", line 177, in _do_get
    return self._create_connection()
           ~~~~~~~~~~~~~~~~~~~~~~~^^
  File "C:\Users\khuat\AppData\Roaming\Python\Python313\site-packages\sqlalchemy\pool\base.py", line 390, in _create_connection
    return _ConnectionRecord(self)
  File "C:\Users\khuat\AppData\Roaming\Python\Python313\site-packages\sqlalchemy\pool\base.py", line 675, in __init__
    self.__connect()
    ~~~~~~~~~~~~~~^^
  File "C:\Users\khuat\AppData\Roaming\Python\Python313\site-packages\sqlalchemy\pool\base.py", line 901, in __connect
    with util.safe_reraise():
         ~~~~~~~~~~~~~~~~~^^
  File "C:\Users\khuat\AppData\Roaming\Python\Python313\site-packages\sqlalchemy\util\langhelpers.py", line 146, in __exit__
    raise exc_value.with_traceback(exc_tb)
  File "C:\Users\khuat\AppData\Roaming\Python\Python313\site-packages\sqlalchemy\pool\base.py", line 897, in __connect
    self.dbapi_connection = connection = pool._invoke_creator(self)
                                         ~~~~~~~~~~~~~~~~~~~~^^^^^^
  File "C:\Users\khuat\AppData\Roaming\Python\Python313\site-packages\sqlalchemy\engine\create.py", line 646, in connect
    return dialect.connect(*cargs, **cparams)
           ~~~~~~~~~~~~~~~^^^^^^^^^^^^^^^^^^^
  File "C:\Users\khuat\AppData\Roaming\Python\Python313\site-packages\sqlalchemy\engine\default.py", line 625, in connect
    return self.loaded_dbapi.connect(*cargs, **cparams)  # type: ignore[no-any-return]  # NOQA: E501
           ~~~~~~~~~~~~~~~~~~~~~~~~~^^^^^^^^^^^^^^^^^^^
pyodbc.Error: ('IM012', '[IM012] [Microsoft][ODBC Driver Manager] DRIVER keyword syntax error (0) (SQLDriverConnect)')

The above exception was the direct cause of the following exception:

Traceback (most recent call last):
  File "c:\Studii\ltweb\database\models.py", line 177, in initialize_database
    Base.metadata.create_all(bind=engine)
    ~~~~~~~~~~~~~~~~~~~~~~~~^^^^^^^^^^^^^
  File "C:\Users\khuat\AppData\Roaming\Python\Python313\site-packages\sqlalchemy\sql\schema.py", line 5925, in create_all
    bind._run_ddl_visitor(
    ~~~~~~~~~~~~~~~~~~~~~^
        ddl.SchemaGenerator, self, checkfirst=checkfirst, tables=tables
        ^^^^^^^^^^^^^^^^^^^^^^^^^^^^^^^^^^^^^^^^^^^^^^^^^^^^^^^^^^^^^^^
    )
    ^
  File "C:\Users\khuat\AppData\Roaming\Python\Python313\site-packages\sqlalchemy\engine\base.py", line 3248, in _run_ddl_visitor
    with self.begin() as conn:
         ~~~~~~~~~~^^
  File "C:\Python313\Lib\contextlib.py", line 141, in __enter__
    return next(self.gen)
  File "C:\Users\khuat\AppData\Roaming\Python\Python313\site-packages\sqlalchemy\engine\base.py", line 3238, in begin
    with self.connect() as conn:
         ~~~~~~~~~~~~^^
  File "C:\Users\khuat\AppData\Roaming\Python\Python313\site-packages\sqlalchemy\engine\base.py", line 3274, in connect
    return self._connection_cls(self)
           ~~~~~~~~~~~~~~~~~~~~^^^^^^
  File "C:\Users\khuat\AppData\Roaming\Python\Python313\site-packages\sqlalchemy\engine\base.py", line 148, in __init__
    Connection._handle_dbapi_exception_noconnection(
    ~~~~~~~~~~~~~~~~~~~~~~~~~~~~~~~~~~~~~~~~~~~~~~~^
        err, dialect, engine
        ^^^^^^^^^^^^^^^^^^^^
    )
    ^
  File "C:\Users\khuat\AppData\Roaming\Python\Python313\site-packages\sqlalchemy\engine\base.py", line 2439, in _handle_dbapi_exception_noconnection
    raise sqlalchemy_exception.with_traceback(exc_info[2]) from e
  File "C:\Users\khuat\AppData\Roaming\Python\Python313\site-packages\sqlalchemy\engine\base.py", line 146, in __init__
    self._dbapi_connection = engine.raw_connection()
                             ~~~~~~~~~~~~~~~~~~~~~^^
  File "C:\Users\khuat\AppData\Roaming\Python\Python313\site-packages\sqlalchemy\engine\base.py", line 3298, in raw_connection
    return self.pool.connect()
           ~~~~~~~~~~~~~~~~~^^
  File "C:\Users\khuat\AppData\Roaming\Python\Python313\site-packages\sqlalchemy\pool\base.py", line 449, in connect
    return _ConnectionFairy._checkout(self)
           ~~~~~~~~~~~~~~~~~~~~~~~~~~^^^^^^
  File "C:\Users\khuat\AppData\Roaming\Python\Python313\site-packages\sqlalchemy\pool\base.py", line 1264, in _checkout
    fairy = _ConnectionRecord.checkout(pool)
  File "C:\Users\khuat\AppData\Roaming\Python\Python313\site-packages\sqlalchemy\pool\base.py", line 713, in checkout
    rec = pool._do_get()
  File "C:\Users\khuat\AppData\Roaming\Python\Python313\site-packages\sqlalchemy\pool\impl.py", line 179, in _do_get
    with util.safe_reraise():
         ~~~~~~~~~~~~~~~~~^^
  File "C:\Users\khuat\AppData\Roaming\Python\Python313\site-packages\sqlalchemy\util\langhelpers.py", line 146, in __exit__
    raise exc_value.with_traceback(exc_tb)
  File "C:\Users\khuat\AppData\Roaming\Python\Python313\site-packages\sqlalchemy\pool\impl.py", line 177, in _do_get
    return self._create_connection()
           ~~~~~~~~~~~~~~~~~~~~~~~^^
  File "C:\Users\khuat\AppData\Roaming\Python\Python313\site-packages\sqlalchemy\pool\base.py", line 390, in _create_connection
    return _ConnectionRecord(self)
  File "C:\Users\khuat\AppData\Roaming\Python\Python313\site-packages\sqlalchemy\pool\base.py", line 675, in __init__
    self.__connect()
    ~~~~~~~~~~~~~~^^
  File "C:\Users\khuat\AppData\Roaming\Python\Python313\site-packages\sqlalchemy\pool\base.py", line 901, in __connect
    with util.safe_reraise():
         ~~~~~~~~~~~~~~~~~^^
  File "C:\Users\khuat\AppData\Roaming\Python\Python313\site-packages\sqlalchemy\util\langhelpers.py", line 146, in __exit__
    raise exc_value.with_traceback(exc_tb)
  File "C:\Users\khuat\AppData\Roaming\Python\Python313\site-packages\sqlalchemy\pool\base.py", line 897, in __connect
    self.dbapi_connection = connection = pool._invoke_creator(self)
                                         ~~~~~~~~~~~~~~~~~~~~^^^^^^
  File "C:\Users\khuat\AppData\Roaming\Python\Python313\site-packages\sqlalchemy\engine\create.py", line 646, in connect
    return dialect.connect(*cargs, **cparams)
           ~~~~~~~~~~~~~~~^^^^^^^^^^^^^^^^^^^
  File "C:\Users\khuat\AppData\Roaming\Python\Python313\site-packages\sqlalchemy\engine\default.py", line 625, in connect
    return self.loaded_dbapi.connect(*cargs, **cparams)  # type: ignore[no-any-return]  # NOQA: E501
           ~~~~~~~~~~~~~~~~~~~~~~~~~^^^^^^^^^^^^^^^^^^^
sqlalchemy.exc.DBAPIError: (pyodbc.Error) ('IM012', '[IM012] [Microsoft][ODBC Driver Manager] DRIVER keyword syntax error (0) (SQLDriverConnect)')
(Background on this error at: https://sqlalche.me/e/20/dbapi)
